2023-05-26T00:43:51.666894+0800 INFO Таблица повторилась
2023-05-26T00:43:51.667261+0800 INFO table_name='Октябрьский'
self.get_table_names()=['Октябрьский']
2023-05-26T00:45:15.931326+0800 INFO Таблица повторилась
2023-05-26T00:45:15.931618+0800 INFO table_name='Октябрьский'
2023-05-26T00:45:15.931802+0800 INFO self.get_table_names()=['Октябрьский']
2023-05-26T00:45:57.894422+0800 INFO Таблица повторилась
2023-05-26T00:45:57.894694+0800 INFO table_name='Октябрьский'
2023-05-26T00:45:57.894869+0800 INFO self.get_table_names()=['Октябрьский']
2023-05-26T00:46:27.537146+0800 ERROR An error has been caught in function 'import_data', process 'MainProcess' (10406), thread 'MainThread' (4580609536):
Traceback (most recent call last):

  File "/Users/ivkrak/programming/kakasha_project/qt_app.py", line 101, in <module>
    sys.exit(app.exec_())
    │   │    │   └ <built-in method exec_>
    │   │    └ <PyQt5.QtWidgets.QApplication object at 0x1109bfbe0>
    │   └ <built-in function exit>
    └ <module 'sys' (built-in)>

> File "/Users/ivkrak/programming/kakasha_project/qt_app.py", line 63, in import_data
    table_name = db.load_excel_data(file_path=fileName)
                 │  │                         └ ''
                 │  └ <function ExcelDatabase.load_excel_data at 0x11fb500e0>
                 └ <main.ExcelDatabase object at 0x1368bc7d0>

  File "/Users/ivkrak/programming/kakasha_project/main.py", line 63, in load_excel_data
    df = pd.read_excel(file_path)
         │  │          └ ''
         │  └ <function read_excel at 0x11eea3560>
         └ <module 'pandas' from '/Users/ivkrak/programming/kakasha_project/venv/lib/python3.11/site-packages/pandas/__init__.py'>

  File "/Users/ivkrak/programming/kakasha_project/venv/lib/python3.11/site-packages/pandas/io/excel/_base.py", line 478, in read_excel
    io = ExcelFile(io, storage_options=storage_options, engine=engine)
         │         │                   │                       └ None
         │         │                   └ None
         │         └ ''
         └ <class 'pandas.io.excel._base.ExcelFile'>
  File "/Users/ivkrak/programming/kakasha_project/venv/lib/python3.11/site-packages/pandas/io/excel/_base.py", line 1496, in __init__
    ext = inspect_excel_format(
          └ <function inspect_excel_format at 0x11ef02200>
  File "/Users/ivkrak/programming/kakasha_project/venv/lib/python3.11/site-packages/pandas/io/excel/_base.py", line 1371, in inspect_excel_format
    with get_handle(
         └ <function get_handle at 0x11e945940>
  File "/Users/ivkrak/programming/kakasha_project/venv/lib/python3.11/site-packages/pandas/io/common.py", line 868, in get_handle
    handle = open(handle, ioargs.mode)
                  │       │      └ 'rb'
                  │       └ IOArgs(filepath_or_buffer='', encoding='utf-8', mode='rb', compression={'method': None}, should_close=False)
                  └ ''

FileNotFoundError: [Errno 2] No such file or directory: ''
2023-05-26T00:46:38.866354+0800 INFO Таблица повторилась
2023-05-26T00:46:38.866667+0800 INFO table_name='Октябрьский'
2023-05-26T00:46:38.866885+0800 INFO self.get_table_names()=['Октябрьский']
2023-05-26T00:47:55.565223+0800 INFO Таблица повторилась
2023-05-26T00:47:55.565501+0800 INFO table_name='Октябрьский'
2023-05-26T00:47:55.565683+0800 INFO self.get_table_names()=['Октябрьский']
2023-05-26T00:47:55.565848+0800 INFO CREATE_DCT_FROM_TABLE table_name='Октябрьский'
